Workbook

Sheet Table of Contents
A1: Table of Contents
A2: Sheet Name | B2: Description
A3: Executive Summary | B3: High-level summary of key insights, findings, and conclusions derived from the analysis.
A4: conversion_funnel | B4: Analysis of customer conversion rates across key event stages within funnel.
A5: cohort_analysis | B5: Analytical view of customer retention patterns by cohort, grouped by first purchase date and tracked accross cohort ages.
A6: retention_rates | B6: Calculation of customer retention rates across cohort ages based on first purchase dates.
A7: purchase_activity | B7: Processed purchase activity data derived from raw user activity and filtered by purchase events.
A8: first_purchase_date | B8: Derived table identifying each customer’s first recorded purchase date.
A9: raw_user_activity | B9: Raw, unprocessed user activity data used as the primary data source for analysis.
A14: Legend
A15: Summaries
A16: Analysis
A17: Calculations
A18: Raw Data

Sheet Executive Summary
A1: Executive Summary
A4: Results | B4: Synopsis
A5: Conversion Funnel | B5: The overall customer conversion rate is 10.34%, calculated across the three key funnel event types.
A6: Retention Rates | B6: Customer retention rates are relatively low when analyzed by first purchase month across the observed cohort ages.
A9: Analysis | B9: Description
A10: Raw Data | B10: The raw data was filtered and used as the primary data source for the entire analysis. It includes event dates, user IDs, and event types, which form the foundation for all subsequent analyses.
A11: Conversion Funnel | B11: The conversion funnel is structured using three key event types and analyzes customer progression through each stage based on counts of unique users per event.
A12: Retention Rates | B12: Retention rates are calculated based on the number of unique customers, grouped by their first purchase month and tracked across cohort ages to evaluate repeat customer behavior over time.

Sheet conversion_funnel
A1: event_type | B1: COUNTUNIQUE of user_id | C1: conversion_rate | D1: total_conversion_rate
A2: view | B2: 10453
A3: shopping_cart | B3: 3036 | C3: =B3/B2 -> 0.29044294 | D3: =B3/$B2 -> 0.29044294
A4: purchase | B4: 1081 | C4: =B4/B3 -> 0.35606061 | D4: =B4/B2 -> 0.10341529

Sheet cohort_analysis
A1: COUNTUNIQUE of user_id | B1: cohort_age
A2: first_purchase_month | B2: 0 | C2: 1 | D2: 2 | E2: 3 | F2: 4
A3: 2020-09 | B3: 32 | C3: 4 | D3: 2 | F3: 1
A4: 2020-10 | B4: 187 | C4: 14 | D4: 7 | E4: 1 | F4: 1
A5: 2020-11 | B5: 238 | C5: 13 | D5: 7 | E5: 1
A6: 2020-12 | B6: 203 | C6: 9 | D6: 6
A7: 2021-01 | B7: 233 | C7: 16
A8: 2021-02 | B8: 188

Sheet retention_rates
B1: cohort_age
A2: first_purchase_month | B2: 1 | C2: 2 | D2: 3 | E2: 4
A3: 2020-09 | B3: =cohort_analysis!C3/cohort_analysis!$B3 -> 0.125 | C3: =cohort_analysis!D3/cohort_analysis!$B3 -> 0.0625 | D3: =cohort_analysis!E3/cohort_analysis!$B3 -> 0 | E3: =cohort_analysis!F3/cohort_analysis!$B3 -> 0.03125
A4: 2020-10 | B4: =cohort_analysis!C4/cohort_analysis!$B4 -> 0.07486631 | C4: =cohort_analysis!D4/cohort_analysis!$B4 -> 0.037433155 | D4: =cohort_analysis!E4/cohort_analysis!$B4 -> 0.0053475936 | E4: =cohort_analysis!F4/cohort_analysis!$B4 -> 0.0053475936
A5: 2020-11 | B5: =cohort_analysis!C5/cohort_analysis!$B5 -> 0.054621849 | C5: =cohort_analysis!D5/cohort_analysis!$B5 -> 0.029411765 | D5: =cohort_analysis!E5/cohort_analysis!$B5 -> 0.0042016807 | E5: =cohort_analysis!F5/cohort_analysis!$B5 -> 0
A6: 2020-12 | B6: =cohort_analysis!C6/cohort_analysis!$B6 -> 0.044334975 | C6: =cohort_analysis!D6/cohort_analysis!$B6 -> 0.02955665 | D6: =cohort_analysis!E6/cohort_analysis!$B6 -> 0 | E6: =cohort_analysis!F6/cohort_analysis!$B6 -> 0
A7: 2021-01 | B7: =cohort_analysis!C7/cohort_analysis!$B7 -> 0.068669528 | C7: =cohort_analysis!D7/cohort_analysis!$B7 -> 0 | D7: =cohort_analysis!E7/cohort_analysis!$B7 -> 0 | E7: =cohort_analysis!F7/cohort_analysis!$B7 -> 0

Sheet purchase_activity
A1: user_id | B1: event_type | C1: category_code | D1: brand | E1: price | F1: event_date | G1: first_purchase_date | H1: event_month | I1: first_purchase_month | J1: cohort_age
A2: a1515915625519397646 | B2: purchase | C2: computers.peripherals.camera | D2: logitech | E2: 123.35 | F2: 44098 | G2: =VLOOKUP(A2,first_purchase_date!A:B,2,false) -> 44098 | H2: =text(F2,"yyyy-mm") -> 2020-09 | I2: =text(G2,"yyyy-mm") -> 2020-09 | J2: =datedif(I2,H2,"m") -> 0
A3: a1515915625519397646 | B3: purchase | C3: computers.peripherals.camera | D3: logitech | E3: 123.35 | F3: 44098 | G3: =VLOOKUP(A3,first_purchase_date!A:B,2,false) -> 44098 | H3: =text(F3,"yyyy-mm") -> 2020-09 | I3: =text(G3,"yyyy-mm") -> 2020-09 | J3: =datedif(I3,H3,"m") -> 0
A4: a1515915625519397646 | B4: purchase | C4: computers.peripherals.camera | D4: logitech | E4: 123.35 | F4: 44098 | G4: =VLOOKUP(A4,first_purchase_date!A:B,2,false) -> 44098 | H4: =text(F4,"yyyy-mm") -> 2020-09 | I4: =text(G4,"yyyy-mm") -> 2020-09 | J4: =datedif(I4,H4,"m") -> 0
A5: a1515915625358482476 | B5: purchase | C5: computers.components.tv_tuner | D5: perfeo | E5: 19.49 | F5: 44098 | G5: =VLOOKUP(A5,first_purchase_date!A:B,2,false) -> 44098 | H5: =text(F5,"yyyy-mm") -> 2020-09 | I5: =text(G5,"yyyy-mm") -> 2020-09 | J5: =datedif(I5,H5,"m") -> 0
A6: a1515915625519463641 | B6: purchase | C6: stationery.cartrige | D6: hp | E6: 71.02 | F6: 44098 | G6: =VLOOKUP(A6,first_purchase_date!A:B,2,false) -> 44098 | H6: =text(F6,"yyyy-mm") -> 2020-09 | I6: =text(G6,"yyyy-mm") -> 2020-09 | J6: =datedif(I6,H6,"m") -> 0
A7: a1515915625519463641 | B7: purchase | C7: stationery.cartrige | D7: hp | E7: 71.02 | F7: 44098 | G7: =VLOOKUP(A7,first_purchase_date!A:B,2,false) -> 44098 | H7: =text(F7,"yyyy-mm") -> 2020-09 | I7: =text(G7,"yyyy-mm") -> 2020-09 | J7: =datedif(I7,H7,"m") -> 0
A8: a1515915625519463641 | B8: purchase | C8: stationery.cartrige | D8: hp | E8: 71.02 | F8: 44098 | G8: =VLOOKUP(A8,first_purchase_date!A:B,2,false) -> 44098 | H8: =text(F8,"yyyy-mm") -> 2020-09 | I8: =text(G8,"yyyy-mm") -> 2020-09 | J8: =datedif(I8,H8,"m") -> 0
A9: a1515915625503751892 | B9: purchase | C9: appliances.environment.vacuum | D9: topon | E9: 35.87 | F9: 44098 | G9: =VLOOKUP(A9,first_purchase_date!A:B,2,false) -> 44098 | H9: =text(F9,"yyyy-mm") -> 2020-09 | I9: =text(G9,"yyyy-mm") -> 2020-09 | J9: =datedif(I9,H9,"m") -> 0
A10: a1515915625519463641 | B10: purchase | C10: stationery.cartrige | D10: hp | E10: 71.02 | F10: 44098 | G10: =VLOOKUP(A10,first_purchase_date!A:B,2,false) -> 44098 | H10: =text(F10,"yyyy-mm") -> 2020-09 | I10: =text(G10,"yyyy-mm") -> 2020-09 | J10: =datedif(I10,H10,"m") -> 0
A11: a1515915625385888878 | B11: purchase | C11: stationery.cartrige | D11: cactus | E11: 24.73 | F11: 44099 | G11: =VLOOKUP(A11,first_purchase_date!A:B,2,false) -> 44099 | H11: =text(F11,"yyyy-mm") -> 2020-09 | I11: =text(G11,"yyyy-mm") -> 2020-09 | J11: =datedif(I11,H11,"m") -> 0
A12: a1515915625385888878 | B12: purchase | C12: stationery.cartrige | D12: cactus | E12: 24.73 | F12: 44099 | G12: =VLOOKUP(A12,first_purchase_date!A:B,2,false) -> 44099 | H12: =text(F12,"yyyy-mm") -> 2020-09 | I12: =text(G12,"yyyy-mm") -> 2020-09 | J12: =datedif(I12,H12,"m") -> 0
A13: a1515915625519762021 | B13: purchase | D13: kitfort | E13: 140.63 | F13: 44099 | G13: =VLOOKUP(A13,first_purchase_date!A:B,2,false) -> 44099 | H13: =text(F13,"yyyy-mm") -> 2020-09 | I13: =text(G13,"yyyy-mm") -> 2020-09 | J13: =datedif(I13,H13,"m") -> 0
A14: a1515915625519762021 | B14: purchase | D14: kitfort | E14: 140.63 | F14: 44099 | G14: =VLOOKUP(A14,first_purchase_date!A:B,2,false) -> 44099 | H14: =text(F14,"yyyy-mm") -> 2020-09 | I14: =text(G14,"yyyy-mm") -> 2020-09 | J14: =datedif(I14,H14,"m") -> 0
A15: a1515915625520029989 | B15: purchase | C15: stationery.cartrige | D15: hp | E15: 29.57 | F15: 44100 | G15: =VLOOKUP(A15,first_purchase_date!A:B,2,false) -> 44100 | H15: =text(F15,"yyyy-mm") -> 2020-09 | I15: =text(G15,"yyyy-mm") -> 2020-09 | J15: =datedif(I15,H15,"m") -> 0
A16: a1515915625520049345 | B16: purchase | C16: auto.accessories.player | D16: kenwood | E16: 104.86 | F16: 44100 | G16: =VLOOKUP(A16,first_purchase_date!A:B,2,false) -> 44100 | H16: =text(F16,"yyyy-mm") -> 2020-09 | I16: =text(G16,"yyyy-mm") -> 2020-09 | J16: =datedif(I16,H16,"m") -> 0
A17: a1515915625520070184 | B17: purchase | C17: computers.peripherals.printer | D17: epson | E17: 647.29 | F17: 44100 | G17: =VLOOKUP(A17,first_purchase_date!A:B,2,false) -> 44100 | H17: =text(F17,"yyyy-mm") -> 2020-09 | I17: =text(G17,"yyyy-mm") -> 2020-09 | J17: =datedif(I17,H17,"m") -> 0
A18: a1515915625520070184 | B18: purchase | C18: computers.peripherals.printer | D18: epson | E18: 647.29 | F18: 44100 | G18: =VLOOKUP(A18,first_purchase_date!A:B,2,false) -> 44100 | H18: =text(F18,"yyyy-mm") -> 2020-09 | I18: =text(G18,"yyyy-mm") -> 2020-09 | J18: =datedif(I18,H18,"m") -> 0
A19: a1515915625520070184 | B19: purchase | C19: computers.peripherals.printer | D19: epson | E19: 647.29 | F19: 44100 | G19: =VLOOKUP(A19,first_purchase_date!A:B,2,false) -> 44100 | H19: =text(F19,"yyyy-mm") -> 2020-09 | I19: =text(G19,"yyyy-mm") -> 2020-09 | J19: =datedif(I19,H19,"m") -> 0
A20: a1515915625520227072 | B20: purchase | C20: computers.peripherals.wifi | D20: ubiquiti | E20: 155.43 | F20: 44101 | G20: =VLOOKUP(A20,first_purchase_date!A:B,2,false) -> 44101 | H20: =text(F20,"yyyy-mm") -> 2020-09 | I20: =text(G20,"yyyy-mm") -> 2020-09 | J20: =datedif(I20,H20,"m") -> 0
A21: a1515915625520227072 | B21: purchase | C21: computers.peripherals.wifi | D21: ubiquiti | E21: 130.73 | F21: 44101 | G21: =VLOOKUP(A21,first_purchase_date!A:B,2,false) -> 44101 | H21: =text(F21,"yyyy-mm") -> 2020-09 | I21: =text(G21,"yyyy-mm") -> 2020-09 | J21: =datedif(I21,H21,"m") -> 0
A22: a1515915625520227072 | B22: purchase | C22: computers.peripherals.wifi | D22: ubiquiti | E22: 155.43 | F22: 44102 | G22: =VLOOKUP(A22,first_purchase_date!A:B,2,false) -> 44101 | H22: =text(F22,"yyyy-mm") -> 2020-09 | I22: =text(G22,"yyyy-mm") -> 2020-09 | J22: =datedif(I22,H22,"m") -> 0
A23: a1515915625371158307 | B23: purchase | C23: stationery.cartrige | D23: cactus | E23: 20.14 | F23: 44102 | G23: =VLOOKUP(A23,first_purchase_date!A:B,2,false) -> 44102 | H23: =text(F23,"yyyy-mm") -> 2020-09 | I23: =text(G23,"yyyy-mm") -> 2020-09 | J23: =datedif(I23,H23,"m") -> 0
A24: a1515915625371158307 | B24: purchase | C24: stationery.cartrige | D24: cactus | E24: 20.14 | F24: 44102 | G24: =VLOOKUP(A24,first_purchase_date!A:B,2,false) -> 44102 | H24: =text(F24,"yyyy-mm") -> 2020-09 | I24: =text(G24,"yyyy-mm") -> 2020-09 | J24: =datedif(I24,H24,"m") -> 0
A25: a1515915625371158307 | B25: purchase | C25: stationery.cartrige | D25: cactus | E25: 20.14 | F25: 44102 | G25: =VLOOKUP(A25,first_purchase_date!A:B,2,false) -> 44102 | H25: =text(F25,"yyyy-mm") -> 2020-09 | I25: =text(G25,"yyyy-mm") -> 2020-09 | J25: =datedif(I25,H25,"m") -> 0
A26: a1515915625371158307 | B26: purchase | C26: computers.peripherals.printer | D26: canon | E26: 192.86 | F26: 44102 | G26: =VLOOKUP(A26,first_purchase_date!A:B,2,false) -> 44102 | H26: =text(F26,"yyyy-mm") -> 2020-09 | I26: =text(G26,"yyyy-mm") -> 2020-09 | J26: =datedif(I26,H26,"m") -> 0
... A32: a1515915625520413119 | B32: purchase | C32: stationery.cartrige | D32: nv-print | E32: 17.62 | F32: 44102 | G32: =VLOOKUP(A32,first_purchase_date!A:B,2,false) -> 44102 | H32: =text(F32,"yyyy-mm") -> 2020-09 | I32: =text(G32,"yyyy-mm") -> 2020-09 | J32: =datedif(I32,H32,"m") -> 0
A33: a1515915625519991781 | B33: purchase | C33: computers.peripherals.printer | E33: 10.78 | F33: 44102 | G33: =VLOOKUP(A33,first_purchase_date!A:B,2,false) -> 44102 | H33: =text(F33,"yyyy-mm") -> 2020-09 | I33: =text(G33,"yyyy-mm") -> 2020-09 | J33: =datedif(I33,H33,"m") -> 0
A34: a1515915625519991781 | B34: purchase | C34: computers.peripherals.printer | E34: 10.78 | F34: 44102 | G34: =VLOOKUP(A34,first_purchase_date!A:B,2,false) -> 44102 | H34: =text(F34,"yyyy-mm") -> 2020-09 | I34: =text(G34,"yyyy-mm") -> 2020-09 | J34: =datedif(I34,H34,"m") -> 0
A35: a1515915625519991781 | B35: purchase | C35: computers.peripherals.printer | E35: 10.84 | F35: 44102 | G35: =VLOOKUP(A35,first_purchase_date!A:B,2,false) -> 44102 | H35: =text(F35,"yyyy-mm") -> 2020-09 | I35: =text(G35,"yyyy-mm") -> 2020-09 | J35: =datedif(I35,H35,"m") -> 0
A36: a1515915625519991781 | B36: purchase | C36: computers.peripherals.printer | E36: 10.78 | F36: 44102 | G36: =VLOOKUP(A36,first_purchase_date!A:B,2,false) -> 44102 | H36: =text(F36,"yyyy-mm") -> 2020-09 | I36: =text(G36,"yyyy-mm") -> 2020-09 | J36: =datedif(I36,H36,"m") -> 0
A37: a1515915625520433043 | B37: purchase | D37: a-data | E37: 17.89 | F37: 44102 | G37: =VLOOKUP(A37,first_purchase_date!A:B,2,false) -> 44102 | H37: =text(F37,"yyyy-mm") -> 2020-09 | I37: =text(G37,"yyyy-mm") -> 2020-09 | J37: =datedif(I37,H37,"m") -> 0
A38: a1515915625520569929 | B38: purchase | C38: electronics.tablet | E38: 12.25 | F38: 44102 | G38: =VLOOKUP(A38,first_purchase_date!A:B,2,false) -> 44102 | H38: =text(F38,"yyyy-mm") -> 2020-09 | I38: =text(G38,"yyyy-mm") -> 2020-09 | J38: =datedif(I38,H38,"m") -> 0
A39: a1515915625520569929 | B39: purchase | C39: electronics.tablet | E39: 12.25 | F39: 44102 | G39: =VLOOKUP(A39,first_purchase_date!A:B,2,false) -> 44102 | H39: =text(F39,"yyyy-mm") -> 2020-09 | I39: =text(G39,"yyyy-mm") -> 2020-09 | J39: =datedif(I39,H39,"m") -> 0
A40: a1515915625520569929 | B40: purchase | C40: electronics.tablet | E40: 12.25 | F40: 44102 | G40: =VLOOKUP(A40,first_purchase_date!A:B,2,false) -> 44102 | H40: =text(F40,"yyyy-mm") -> 2020-09 | I40: =text(G40,"yyyy-mm") -> 2020-09 | J40: =datedif(I40,H40,"m") -> 0
A41: a1515915625520569929 | B41: purchase | C41: electronics.tablet | E41: 12.25 | F41: 44102 | G41: =VLOOKUP(A41,first_purchase_date!A:B,2,false) -> 44102 | H41: =text(F41,"yyyy-mm") -> 2020-09 | I41: =text(G41,"yyyy-mm") -> 2020-09 | J41: =datedif(I41,H41,"m") -> 0
A42: a1515915625520569929 | B42: purchase | C42: electronics.tablet | E42: 12.25 | F42: 44102 | G42: =VLOOKUP(A42,first_purchase_date!A:B,2,false) -> 44102 | H42: =text(F42,"yyyy-mm") -> 2020-09 | I42: =text(G42,"yyyy-mm") -> 2020-09 | J42: =datedif(I42,H42,"m") -> 0
A43: a1515915625503751892 | B43: purchase | C43: appliances.environment.vacuum | D43: topon | E43: 35.87 | F43: 44102 | G43: =VLOOKUP(A43,first_purchase_date!A:B,2,false) -> 44098 | H43: =text(F43,"yyyy-mm") -> 2020-09 | I43: =text(G43,"yyyy-mm") -> 2020-09 | J43: =datedif(I43,H43,"m") -> 0
A44: a1515915625503751892 | B44: purchase | C44: appliances.environment.vacuum | D44: topon | E44: 35.87 | F44: 44102 | G44: =VLOOKUP(A44,first_purchase_date!A:B,2,false) -> 44098 | H44: =text(F44,"yyyy-mm") -> 2020-09 | I44: =text(G44,"yyyy-mm") -> 2020-09 | J44: =datedif(I44,H44,"m") -> 0
A45: a1515915625520609702 | B45: purchase | D45: moxom | E45: 15.71 | F45: 44102 | G45: =VLOOKUP(A45,first_purchase_date!A:B,2,false) -> 44102 | H45: =text(F45,"yyyy-mm") -> 2020-09 | I45: =text(G45,"yyyy-mm") -> 2020-09 | J45: =datedif(I45,H45,"m") -> 0
...

Sheet first_purchase_date

Sheet raw_user_activity
A1: user_id | B1: event_type | C1: category_code | D1: brand | E1: price | F1: event_date
A2: a1515915625519014356 | B2: view | C2: computers.peripherals.printer | D2: pantum | E2: 113.81 | F2: 44098
A3: a1515915625519392599 | B3: view | C3: stationery.cartrige | D3: lomond | E3: 8.35 | F3: 44098
A4: a1515915625369253995 | B4: view | C4: construction.tools.welding | E4: 250.63 | F4: 44098
A5: a1515915625369253995 | B5: view | C5: construction.tools.welding | E5: 250.63 | F5: 44098
A6: a1515915625519410002 | B6: view | C6: computers.desktop | D6: steelseries | E6: 58.49 | F6: 44098
A7: a1515915625519413944 | B7: view | C7: appliances.kitchen.microwave | D7: samsung | E7: 130.11 | F7: 44098
A8: a1515915625519397646 | B8: view | C8: computers.peripherals.camera | D8: logitech | E8: 123.35 | F8: 44098
A9: a1515915625519397646 | B9: shopping_cart | C9: computers.peripherals.camera | D9: logitech | E9: 123.35 | F9: 44098
A10: a1515915625519397646 | B10: purchase | C10: computers.peripherals.camera | D10: logitech | E10: 123.35 | F10: 44098
A11: a1515915625519397646 | B11: view | C11: computers.peripherals.camera | D11: logitech | E11: 123.35 | F11: 44098
A12: a1515915625519417750 | B12: view | C12: computers.network.router | D12: d-link | E12: 53.14 | F12: 44098
A13: a1515915625519397646 | B13: shopping_cart | C13: computers.peripherals.camera | D13: logitech | E13: 123.35 | F13: 44098
A14: a1515915625519397646 | B14: purchase | C14: computers.peripherals.camera | D14: logitech | E14: 123.35 | F14: 44098
A15: a1515915625519397646 | B15: purchase | C15: computers.peripherals.camera | D15: logitech | E15: 123.35 | F15: 44098
A16: a1515915625358482476 | B16: view | C16: computers.components.tv_tuner | D16: perfeo | E16: 19.49 | F16: 44098
A17: a1515915625358482476 | B17: shopping_cart | C17: computers.components.tv_tuner | D17: perfeo | E17: 19.49 | F17: 44098
... A21: a1515915625519443407 | B21: view | C21: computers.components.motherboard | D21: asrock | E21: 77.73 | F21: 44098
A22: a1515915625519446240 | B22: view | D22: formula | E22: 35.54 | F22: 44098
A23: a1515915625519452732 | B23: view | C23: computers.notebook | D23: hp | E23: 27.62 | F23: 44098
A24: a1515915625519460662 | B24: view | C24: computers.peripherals.joystick | D24: logitech | E24: 162.51 | F24: 44098
A25: a1515915625519460662 | B25: shopping_cart | C25: computers.peripherals.joystick | D25: logitech | E25: 162.51 | F25: 44098
A26: a1515915625519460662 | B26: view | C26: computers.peripherals.joystick | D26: logitech | E26: 162.51 | F26: 44098
A27: a1515915625519460662 | B27: view | C27: computers.peripherals.joystick | D27: logitech | E27: 193.98 | F27: 44098
A28: a1515915625519463641 | B28: view | C28: stationery.cartrige | D28: hp | E28: 71.02 | F28: 44098
A29: a1515915625519463641 | B29: view | C29: stationery.cartrige | D29: hp | E29: 71.02 | F29: 44098
A30: a1515915625517481778 | B30: view | E30: 29.24 | F30: 44098
A31: a1515915625519463641 | B31: shopping_cart | C31: stationery.cartrige | D31: hp | E31: 71.02 | F31: 44098
A32: a1515915625517481778 | B32: view | E32: 29.24 | F32: 44098
A33: a1515915625355805313 | B33: view | C33: appliances.sewing_machine | D33: janome | E33: 470.38 | F33: 44098
A34: a1515915625517481778 | B34: view | E34: 29.24 | F34: 44098
A35: a1515915625355805313 | B35: view | C35: appliances.sewing_machine | D35: janome | E35: 314.97 | F35: 44098
A36: a1515915625517481778 | B36: view | E36: 29.24 | F36: 44098
A37: a1515915625519463641 | B37: purchase | C37: stationery.cartrige | D37: hp | E37: 71.02 | F37: 44098
A38: a1515915625519463641 | B38: purchase | C38: stationery.cartrige | D38: hp | E38: 71.02 | F38: 44098
A39: a1515915625519463641 | B39: purchase | C39: stationery.cartrige | D39: hp | E39: 71.02 | F39: 44098
A40: a1515915625519479471 | B40: view | C40: electronics.telephone | D40: samsung | E40: 798.37 | F40: 44098
A41: a1515915625519479471 | B41: view | C41: electronics.telephone | D41: leeco | E41: 104.13 | F41: 44098
A42: a1515915625503751892 | B42: view | C42: appliances.environment.vacuum | D42: topon | E42: 35.87 | F42: 44098
A43: a1515915625503751892 | B43: view | C43: appliances.environment.vacuum | D43: topon | E43: 35.87 | F43: 44098
...
